2019-07-03 22:21:14,408-common.base_page-INFO-等待元素可见('xpath', '//input[@name="account"]')
2019-07-03 22:21:20,425-common.base_page-ERROR-等待元素可见失败
2019-07-03 22:21:26,446-common.base_page-ERROR-网页截屏失败！
Traceback (most recent call last):
  File "F:\MyProject\web_ketangpai\common\base_page.py", line 24, in wait_ele_visible
    WebDriverWait(self.driver,timeout).until(EC.visibility_of_element_located(loc))
  File "F:\Program Files\Python37\lib\site-packages\selenium\webdriver\support\wait.py", line 71, in until
    value = method(self._driver)
  File "F:\Program Files\Python37\lib\site-packages\selenium\webdriver\support\expected_conditions.py", line 128, in __call__
    return _element_if_visible(_find_element(driver, self.locator))
  File "F:\Program Files\Python37\lib\site-packages\selenium\webdriver\support\expected_conditions.py", line 415, in _find_element
    raise e
  File "F:\Program Files\Python37\lib\site-packages\selenium\webdriver\support\expected_conditions.py", line 411, in _find_element
    return driver.find_element(*by)
  File "F:\Program Files\Python37\lib\site-packages\selenium\webdriver\remote\webdriver.py", line 978, in find_element
    'value': value})['value']
  File "F:\Program Files\Python37\lib\site-packages\selenium\webdriver\remote\webdriver.py", line 321, in execute
    self.error_handler.check_response(response)
  File "F:\Program Files\Python37\lib\site-packages\selenium\webdriver\remote\errorhandler.py", line 242, in check_response
    raise exception_class(message, screen, stacktrace)
selenium.common.exceptions.WebDriverException: Message: chrome not reachable
  (Session info: chrome=75.0.3770.100)
  (Driver info: chromedriver=74.0.3729.6 (255758eccf3d244491b8a1317aa76e1ce10d57e9-refs/branch-heads/3729@{#29}),platform=Windows NT 10.0.17134 x86_64)


During handling of the above exception, another exception occurred:

Traceback (most recent call last):
  File "F:\MyProject\web_ketangpai\common\base_page.py", line 112, in save_web_screenshot
    self.driver.save_screenshot(screenshot_dir +"/" + filepath)
  File "F:\Program Files\Python37\lib\site-packages\selenium\webdriver\remote\webdriver.py", line 1055, in save_screenshot
    return self.get_screenshot_as_file(filename)
  File "F:\Program Files\Python37\lib\site-packages\selenium\webdriver\remote\webdriver.py", line 1032, in get_screenshot_as_file
    png = self.get_screenshot_as_png()
  File "F:\Program Files\Python37\lib\site-packages\selenium\webdriver\remote\webdriver.py", line 1064, in get_screenshot_as_png
    return base64.b64decode(self.get_screenshot_as_base64().encode('ascii'))
  File "F:\Program Files\Python37\lib\site-packages\selenium\webdriver\remote\webdriver.py", line 1074, in get_screenshot_as_base64
    return self.execute(Command.SCREENSHOT)['value']
  File "F:\Program Files\Python37\lib\site-packages\selenium\webdriver\remote\webdriver.py", line 321, in execute
    self.error_handler.check_response(response)
  File "F:\Program Files\Python37\lib\site-packages\selenium\webdriver\remote\errorhandler.py", line 242, in check_response
    raise exception_class(message, screen, stacktrace)
selenium.common.exceptions.WebDriverException: Message: chrome not reachable
  (Session info: chrome=75.0.3770.100)
  (Driver info: chromedriver=74.0.3729.6 (255758eccf3d244491b8a1317aa76e1ce10d57e9-refs/branch-heads/3729@{#29}),platform=Windows NT 10.0.17134 x86_64)

